File: data/24-10-30_CuO/characterization/XRD.csv
[Measurement conditions],
Sample identification,
Comment - 1,"Configuration=Refl Transm Spinner PW3064/60, Owner=User-1, Creation date=10/4/2011 2:53:33 PM"
Comment - 2,Goniometer=PW3050/60 (Theta/Theta); Minimum step size 2Theta:0.001; Minimum step size Omega:0.001
Comment - 3,Sample stage=Reflection-Transmission Spinner PW3064/60; Minimum step size Phi:0.1
Comment - 4,Diffractometer system=XPERT-PRO
Comment - 5,"Measurement program=C:\PANalytical\Data Collector\Programs\FabioD\20-90_0.026_60s_1D.xrdmp, Identifier={75D2FDBE-8ECF-4DAD-B4A8-7F413C6B3A22}"
Comment - 6,Fine Calibration Offset for 2Theta = -0.049 deg
Anode material,Cu
K-Alpha1 wavelength,1.540598
K-Alpha2 wavelength,1.544426
Ratio K-Alpha2/K-Alpha1,0.5
Divergence slit,Fixed
Monochromator used,NO
Generator voltage,40
Tube current,40
File date and time,7/23/2024 9:54
Unit cell,
h k l, 0 0 0
Scan axis,Gonio
Scan range,20.002
Scan step size,0.0262606
No. of points,2666
Scan type,CONTINUOUS
Phi,0
Time per step,56.865
[Scan points],
Angle,Intensity
20.01513028,862
20.06765141,881
20.12017254,853
20.17269367,876
20.2252148,854
20.27773593,864
20.33025706,868
20.38277819,825
20.43529932,887
20.48782045,895
20.54034158,837
20.59286271,905
20.64538384,929
20.69790497,881
20.7504261,900
20.80294723,839
20.85546836,911
20.90798949,874
20.96051062,888
21.01303175,850
21.06555288,902
21.11807401,847
21.17059514,916
21.22311627,866
21.2756374,947
21.32815853,837
21.38067966,869
21.43320079,880
21.48572192,878
21.53824305,861
21.59076418,857
21.64328531,884
21.69580644,844
21.74832757,849
21.8008487,872
21.85336983,865
21.90589096,854
21.95841209,872
22.01093322,867
22.06345435,835
22.11597548,851
22.16849661,874
22.22101774,863
22.27353887,867
22.32606,855
22.37858113,815
22.43110226,837
22.48362339,960
22.53614452,845
22.58866565,925
22.64118678,876
22.69370791,879
22.74622904,850
22.79875017,891
22.8512713,862
22.90379243,851
22.95631356,813
23.00883469,837
23.06135582,894
23.11387695,887
23.16639808,897
23.21891921,878
23.27144034,841
23.32396147,851
23.3764826,848
23.42900373,896
23.48152486,916
23.53404599,857
23.58656712,848
23.63908825,877
23.69160938,921
23.74413051,896
23.79665164,918
23.84917277,900
23.9016939,864
23.95421503,889
24.00673616,857
24.05925729,874
24.11177842,848
24.16429955,880
24.21682068,907
24.26934181,896
24.32186294,937
24.37438407,952
24.4269052,891
24.47942633,959
24.53194746,891
24.58446859,856
24.63698972,859
24.68951085,863
24.74203198,896
24.79455311,908
24.84707424,918
24.89959537,920
24.9521165,860
25.00463763,913
25.05715876,899
25.10967989,864
25.16220102,899
25.21472215,883
25.26724328,917
25.31976441,889
25.37228554,885
25.42480667,921
25.4773278,915
25.52984893,916
25.58237006,874
25.63489119,920
25.68741232,874
25.73993345,918
25.79245458,904
25.84497571,858
25.89749684,929
25.95001797,886
26.0025391,894
26.05506023,852
26.10758136,876
26.16010249,873
26.21262362,839
26.26514475,849
26.31766588,913
26.37018701,895
26.42270814,959
26.47522927,911
26.5277504,910
26.58027153,901
26.63279266,884
26.68531379,864
26.73783492,893
26.79035605,925
26.84287718,868
26.89539831,901
26.94791944,902
27.00044057,915
27.0529617,847
27.10548283,898
27.15800396,959
27.21052509,849
27.26304622,851
27.31556735,928
27.36808848,857
27.42060961,920
27.47313074,896
27.52565187,882
27.578173,876
27.63069413,949
27.68321526,912
27.73573639,944
27.78825752,866
27.84077865,975
27.89329978,921
27.94582091,1009
27.99834204,914
28.05086317,893
28.1033843,920
28.15590543,877
28.20842656,889
28.26094769,940
28.31346882,905
28.36598995,898
28.41851108,898
28.47103221,924
28.52355334,917
28.57607447,981
28.6285956,860
28.68111673,951
28.73363786,914
28.78615899,901
28.83868012,922
28.89120125,840
28.94372238,906
28.99624351,969
29.04876464,953
29.10128577,919
29.1538069,920
29.20632803,923
29.25884916,892
29.31137029,956
29.36389142,922
29.41641255,920
29.46893368,942
29.52145481,931
29.57397594,941
29.62649707,905
29.6790182,916
29.73153933,982
29.78406046,936
29.83658159,964
29.88910272,935
29.94162385,940
29.99414498,971
30.04666611,1004
30.09918724,981
30.15170837,928
30.2042295,945
30.25675063,942
30.30927176,939
30.36179289,935
30.41431402,997
30.46683515,941
30.51935628,903
30.57187741,915
30.62439854,946
30.67691967,970
30.7294408,957
30.78196193,942
30.83448306,930
30.88700419,945
30.93952532,942
30.99204645,915
31.04456758,985
31.09708871,956
31.14960984,962
31.20213097,944
31.2546521,970
31.30717323,949
31.35969436,964
31.41221549,984
31.46473662,963
31.51725775,932
31.56977888,960
31.62230001,1009
31.67482114,975
31.72734227,961
31.7798634,1085
31.83238453,969
31.88490566,996
31.93742679,994
31.98994792,1042
32.04246905,977
32.09499018,1066
32.14751131,1097
32.20003244,1127
32.25255357,1167
32.3050747,1129
32.35759583,1176
32.41011696,1238
32.46263809,1189
32.51515922,1250
32.56768035,1154
32.62020149,1207
32.67272262,1150
32.72524375,1101
32.77776488,1051
32.83028601,986
32.88280714,1000
32.93532827,1057
32.9878494,1029
33.04037053,1043
33.09289166,974
33.14541279,988
33.19793392,943
33.25045505,978
33.30297618,1008
33.35549731,979
33.40801844,917
33.46053957,987
33.5130607,994
33.56558183,1052
33.61810296,1043
33.67062409,1004
33.72314522,1045
33.77566635,1012
33.82818748,1058
33.88070861,1003
33.93322974,966
33.98575087,1076
34.038272,1008
34.09079313,1034
34.14331426,1046
34.19583539,1016
34.24835652,1098
34.30087765,1103
34.35339878,1155
34.40591991,1194
34.45844104,1162
34.51096217,1202
34.5634833,1199
34.61600443,1162
34.66852556,1198
34.72104669,1258
34.77356782,1333
34.82608895,1438
34.87861008,1519
34.93113121,1576
34.98365234,1623
35.03617347,1782
35.0886946,1938
35.14121573,2099
35.19373686,2432
35.24625799,2659
35.29877912,3030
35.35130025,3243
35.40382138,3481
35.45634251,3623
35.50886364,3602
35.56138477,3575
35.6139059,3392
35.66642703,3178
35.71894816,2866
35.77146929,2623
35.82399042,2261
35.87651155,2171
35.92903268,1944
35.98155381,1768
36.03407494,1709
36.08659607,1587
36.1391172,1443
36.19163833,1381
36.24415946,1330
36.29668059,1303
36.34920172,1295
36.40172285,1224
36.45424398,1185
36.50676511,1187
36.55928624,1207
36.61180737,1171
36.6643285,1154
36.71684963,1141
36.76937076,1167
36.82189189,1181
36.87441302,1157
36.92693415,1184
36.97945528,1126
37.03197641,1121
37.08449754,1159
37.13701867,1178
37.1895398,1213
37.24206093,1158
37.29458206,1159
37.34710319,1165
37.39962432,1223
37.45214545,1278
37.50466658,1232
37.55718771,1281
37.60970884,1281
37.66222997,1267
37.7147511,1297
37.76727223,1454
37.81979336,1451
37.87231449,1461
37.92483562,1584
37.97735675,1549
38.02987788,1606
38.08239901,1735
38.13492014,1769
38.18744127,1914
38.2399624,2039
38.29248353,2141
38.34500466,2272
38.39752579,2414
38.45004692,2804
38.50256805,2868
38.55508918,3149
38.60761031,3308
38.66013144,3400
38.71265257,3525
38.7651737,3572
38.81769483,3492
38.87021596,3233
38.92273709,3048
38.97525822,2912
39.02777935,2708
39.08030048,2430
39.13282161,2284
39.18534274,2049
39.23786387,1874
39.290385,1724
39.34290613,1624
39.39542726,1597
39.44794839,1485
39.50046952,1417
39.55299065,1429
39.60551178,1234
39.65803291,1287
39.71055404,1226
39.76307517,1166
39.8155963,1233
39.86811743,1156
39.92063856,1177
39.97315969,1144
40.02568082,1091
40.07820195,1110
40.13072308,1116
40.18324421,1094
40.23576534,1046
40.28828647,1023
40.3408076,1058
40.39332873,1044
40.44584986,1008
40.49837099,1002
40.55089212,1053
40.60341325,1008
40.65593438,988
40.70845551,990
40.76097664,1040
40.81349777,994
40.8660189,945
40.91854003,1020
40.97106116,1001
41.02358229,997
41.07610342,1035
41.12862455,1007
41.18114568,966
41.23366681,972
41.28618794,940
41.33870907,957
41.3912302,983
41.44375133,1042
41.49627246,982
41.54879359,983
41.60131472,999
41.65383585,915
41.70635698,994
41.75887811,922
41.81139924,935
41.86392037,983
41.9164415,956
41.96896263,993
42.02148376,929
42.07400489,972
42.12652602,963
42.17904715,978
42.23156828,943
42.28408941,968
42.33661054,905
42.38913167,951
42.4416528,932
42.49417393,953
42.54669506,970
42.59921619,965
42.65173732,980
42.70425845,987
42.75677958,959
42.80930071,945
42.86182184,962
42.91434297,910
42.9668641,976
43.01938523,957
43.07190636,953
43.12442749,955
43.17694862,936
43.22946975,945
43.28199088,972
43.33451201,961
43.38703314,900
43.43955427,950
43.4920754,947
43.54459653,913
43.59711766,983
43.64963879,965
43.70215992,926
43.75468105,1038
43.80720218,986
43.85972331,957
43.91224444,966
43.96476557,944
44.0172867,921
44.06980783,976
44.12232896,965
44.17485009,964
44.22737122,911
44.27989235,920
44.33241348,914
44.38493461,917
44.43745574,992
44.48997687,935
44.542498,983
44.59501913,953
44.64754026,903
44.70006139,958
44.75258252,904
44.80510365,880
44.85762478,913
44.91014591,912
44.96266704,973
45.01518817,878
45.0677093,902
45.12023043,976
45.17275156,975
45.22527269,932
45.27779382,1011
45.33031495,935
45.38283608,958
45.43535721,964
45.48787834,981
45.54039947,912
45.5929206,968
45.64544173,997
45.69796286,959
45.75048399,954
45.80300512,958
45.85552625,929
45.90804738,895
45.96056851,959
46.01308964,910
46.06561077,1002
46.1181319,998
46.17065303,987
46.22317416,997
46.27569529,960
46.32821642,984
46.38073755,982
46.43325868,1039
46.48577981,1002
46.53830094,939
46.59082207,1016
46.6433432,970
46.69586433,1011
46.74838546,958
46.80090659,1006
46.85342772,967
46.90594885,949
46.95846998,959
47.01099111,954
47.06351224,983
47.11603337,958
47.1685545,981
47.22107563,1003
47.27359676,1023
47.32611789,971
47.37863902,930
47.43116015,943
47.48368128,969
47.53620241,1007
47.58872354,980
47.64124467,912
47.6937658,988
47.74628693,973
47.79880806,1020
47.85132919,1003
47.90385032,1038
47.95637145,1041
48.00889258,1090
48.06141371,1140
48.11393484,1083
48.16645597,1140
48.2189771,1163
48.27149823,1157
48.32401936,1232
48.37654049,1275
48.42906162,1316
48.48158275,1364
48.53410388,1380
48.58662501,1472
48.63914614,1532
48.69166727,1563
48.7441884,1491
48.79670953,1481
48.84923066,1586
48.90175179,1456
48.95427292,1441
49.00679405,1418
49.05931518,1317
49.11183631,1292
49.16435744,1222
49.21687857,1196
49.2693997,1194
49.32192083,1183
49.37444196,1118
49.42696309,1109
49.47948422,1077
49.53200535,1081
49.58452648,1051
49.63704761,1113
49.68956874,988
49.74208987,1091
49.794611,1045
49.84713213,1052
49.89965326,1011
49.95217439,1051
50.00469552,989
50.05721665,917
50.10973778,1043
50.16225891,982
50.21478004,982
50.26730117,999
50.3198223,971
50.37234343,942
50.42486456,980
50.47738569,951
50.52990682,978
50.58242795,966
50.63494908,935
50.68747021,911
50.73999134,972
50.79251247,979
50.8450336,1009
50.89755473,931
50.95007586,1015
51.00259699,945
51.05511812,984
51.10763925,983
51.16016038,965
51.21268151,946
51.26520264,981
51.31772377,951
51.3702449,998
51.42276603,1004
51.47528716,966
51.52780829,903
51.58032942,1041
51.63285055,983
51.68537168,936
51.73789281,923
51.79041394,968
51.84293507,966
51.8954562,936
51.94797733,1021
52.00049846,918
52.05301959,973
52.10554072,972
52.15806185,997
52.21058298,974
52.26310411,918
52.31562524,954
52.36814637,986
52.4206675,951
52.47318863,973
52.52570976,1092
52.57823089,1010
52.63075202,976
52.68327315,982
52.73579428,984
52.78831541,999
52.84083654,1036
52.89335767,1010
52.9458788,1020
52.99839993,1039
53.05092106,1029
53.10344219,991
53.15596332,1118
53.20848445,1053
53.26100558,1070
53.31352671,1096
53.36604784,1037
53.41856897,1033
53.4710901,1140
53.52361123,1138
53.57613236,1081
53.62865349,1050
53.68117462,1099
53.73369575,1018
53.78621688,1065
53.83873801,1041
53.89125914,1009
53.94378027,1004
53.9963014,1035
54.04882253,1001
54.10134366,933
54.15386479,983
54.20638592,968
54.25890705,924
54.31142818,978
54.36394931,928
54.41647044,952
54.46899157,930
54.5215127,946
54.57403383,941
54.62655496,956
54.67907609,933
54.73159722,978
54.78411835,929
54.83663948,888
54.88916061,977
54.94168174,972
54.99420287,929
55.046724,971
55.09924513,949
55.15176626,935
55.20428739,911
55.25680852,918
55.30932965,987
55.36185078,969
55.41437191,949
55.46689304,911
55.51941417,961
55.5719353,948
55.62445643,943
55.67697756,896
55.72949869,958
55.78201982,907
55.83454095,937
55.88706208,922
55.93958321,950
55.99210434,941
56.04462547,923
56.0971466,951
56.14966773,910
56.20218886,972
56.25470999,896
56.30723112,953
56.35975225,1012
56.41227338,946
56.46479451,1003
56.51731564,947
56.56983677,932
56.6223579,930
56.67487903,926
56.72740016,942
56.77992129,968
56.83244242,1030
56.88496355,988
56.93748468,958
56.99000581,976
57.04252694,1003
57.09504807,952
57.1475692,974
57.20009033,1015
57.25261146,982
57.30513259,1024
57.35765372,1009
57.41017485,1028
57.46269598,992
57.51521711,1073
57.56773824,1036
57.62025937,1036
57.6727805,1035
57.72530163,1045
57.77782276,1117
57.83034389,1169
57.88286502,1130
57.93538615,1128
57.98790728,1166
58.04042841,1146
58.09294954,1150
58.14547067,1173
58.1979918,1176
58.25051293,1172
58.30303406,1191
58.35555519,1192
58.40807632,1250
58.46059745,1167
58.51311858,1168
58.56563971,1130
58.61816084,1052
58.67068197,1109
58.7232031,1102
58.77572423,1009
58.82824536,1032
58.88076649,999
58.93328762,990
58.98580875,1036
59.03832988,996
59.09085101,1010
59.14337214,960
59.19589327,958
59.2484144,975
59.30093553,935
59.35345666,1038
59.40597779,1029
59.45849892,983
59.51102005,921
59.56354118,946
59.61606231,998
59.66858344,963
59.72110457,1014
59.7736257,940
59.82614683,986
59.87866796,979
59.93118909,924
59.98371022,976
60.03623135,956
60.08875248,931
60.14127361,1000
60.19379474,981
60.24631587,974
60.298837,937
60.35135813,1038
60.40387926,948
60.45640039,995
60.50892152,974
60.56144265,1037
60.61396379,1001
60.66648492,978
60.71900605,1014
60.77152718,1073
60.82404831,989
60.87656944,1120
60.92909057,1008
60.9816117,1139
61.03413283,1124
61.08665396,1086
61.13917509,1112
61.19169622,1237
61.24421735,1153
61.29673848,1259
61.34925961,1242
61.40178074,1207
61.45430187,1291
61.506823,1269
61.55934413,1350
61.61186526,1308
61.66438639,1269
61.71690752,1268
61.76942865,1236
61.82194978,1205
61.87447091,1201
61.92699204,1135
61.97951317,1111
62.0320343,1051
62.08455543,1079
62.13707656,1034
62.18959769,1082
62.24211882,1016
62.29463995,1006
62.34716108,972
62.39968221,1036
62.45220334,1045
62.50472447,991
62.5572456,989
62.60976673,979
62.66228786,1005
62.71480899,988
62.76733012,995
62.81985125,980
62.87237238,1031
62.92489351,924
62.97741464,953
63.02993577,960
63.0824569,985
63.13497803,1007
63.18749916,1023
63.24002029,941
63.29254142,966
63.34506255,933
63.39758368,953
63.45010481,946
63.50262594,959
63.55514707,971
63.6076682,1004
63.66018933,964
63.71271046,922
63.76523159,972
63.81775272,1036
63.87027385,1001
63.92279498,1012
63.97531611,971
64.02783724,973
64.08035837,920
64.1328795,1001
64.18540063,987
64.23792176,991
64.29044289,1002
64.34296402,968
64.39548515,983
64.44800628,975
64.50052741,987
64.55304854,1003
64.60556967,965
64.6580908,1008
64.71061193,1036
64.76313306,1032
64.81565419,1068
64.86817532,1066
64.92069645,962
64.97321758,1044
65.02573871,1052
65.07825984,1075
65.13078097,1096
65.1833021,1039
65.23582323,1036
65.28834436,1018
65.34086549,1135
65.39338662,1136
65.44590775,1168
65.49842888,1191
65.55095001,1188
65.60347114,1228
65.65599227,1205
65.7085134,1299
65.76103453,1291
65.81355566,1302
65.86607679,1215
65.91859792,1247
65.97111905,1374
66.02364018,1310
66.07616131,1426
66.12868244,1358
66.18120357,1355
66.2337247,1436
66.28624583,1396
66.33876696,1410
66.39128809,1387
66.44380922,1281
66.49633035,1361
66.54885148,1418
66.60137261,1287
66.65389374,1202
66.70641487,1202
66.758936,1156
66.81145713,1194
66.86397826,1210
66.91649939,1149
66.96902052,1170
67.02154165,1168
67.07406278,1109
67.12658391,1165
67.17910504,1126
67.23162617,1132
67.2841473,1109
67.33666843,1171
67.38918956,1219
67.44171069,1157
67.49423182,1153
67.54675295,1257
67.59927408,1175
67.65179521,1225
67.70431634,1239
67.75683747,1326
67.8093586,1202
67.86187973,1308
67.91440086,1278
67.96692199,1378
68.01944312,1361
68.07196425,1338
68.12448538,1296
68.17700651,1246
68.22952764,1283
68.28204877,1256
68.3345699,1210
68.38709103,1197
68.43961216,1105
68.49213329,1116
68.54465442,1094
68.59717555,1002
68.64969668,1033
68.70221781,1048
68.75473894,1007
68.80726007,1091
68.8597812,1025
68.91230233,1043
68.96482346,1040
69.01734459,1022
69.06986572,1000
69.12238685,1030
69.17490798,953
69.22742911,1000
69.27995024,951
69.33247137,997
69.3849925,911
69.43751363,947
69.49003476,999
69.54255589,951
69.59507702,952
69.64759815,947
69.70011928,1016
69.75264041,1005
69.80516154,1019
69.85768267,984
69.9102038,896
69.96272493,952
70.01524606,942
70.06776719,941
70.12028832,970
70.17280945,861
70.22533058,948
70.27785171,931
70.33037284,950
70.38289397,864
70.4354151,934
70.48793623,903
70.54045736,929
70.59297849,914
70.64549962,901
70.69802075,939
70.75054188,936
70.80306301,933
70.85558414,969
70.90810527,939
70.9606264,903
71.01314753,965
71.06566866,965
71.11818979,939
71.17071092,944
71.22323205,967
71.27575318,972
71.32827431,1000
71.38079544,978
71.43331657,976
71.4858377,952
71.53835883,931
71.59087996,965
71.64340109,982
71.69592222,976
71.74844335,1013
71.80096448,987
71.85348561,1006
71.90600674,1043
71.95852787,1042
72.011049,1006
72.06357013,1011
72.11609126,1037
72.16861239,1045
72.22113352,1009
72.27365465,1058
72.32617578,1059
72.37869691,1056
72.43121804,1080
72.48373917,1074
72.5362603,1024
72.58878143,1066
72.64130256,1015
72.69382369,1041
72.74634482,982
72.79886595,1012
72.85138708,1054
72.90390821,975
72.95642934,987
73.00895047,990
73.0614716,962
73.11399273,981
73.16651386,983
73.21903499,1012
73.27155612,948
73.32407725,972
73.37659838,931
73.42911951,961
73.48164064,944
73.53416177,960
73.5866829,945
73.63920403,988
73.69172516,986
73.74424629,924
73.79676742,876
73.84928855,939
73.90180968,963
73.95433081,937
74.00685194,919
74.05937307,986
74.1118942,999
74.16441533,1001
74.21693646,1013
74.26945759,1015
74.32197872,983
74.37449985,979
74.42702098,978
74.47954211,1011
74.53206324,1021
74.58458437,1009
74.6371055,1012
74.68962663,1086
74.74214776,1070
74.79466889,998
74.84719002,1061
74.89971115,1074
74.95223228,1168
75.00475341,1104
75.05727454,1071
75.10979567,1090
75.1623168,1103
75.21483793,1047
75.26735906,1123
75.31988019,1077
75.37240132,1030
75.42492245,1073
75.47744358,1018
75.52996471,988
75.58248584,1084
75.63500697,1029
75.6875281,1014
75.74004923,922
75.79257036,932
75.84509149,979
75.89761262,1044
75.95013375,972
76.00265488,951
76.05517601,949
76.10769714,979
76.16021827,993
76.2127394,904
76.26526053,945
76.31778166,969
76.37030279,942
76.42282392,886
76.47534505,952
76.52786618,948
76.58038731,926
76.63290844,937
76.68542957,954
76.7379507,960
76.79047183,918
76.84299296,894
76.89551409,923
76.94803522,916
77.00055635,928
77.05307748,936
77.10559861,928
77.15811974,879
77.21064087,954
77.263162,945
77.31568313,934
77.36820426,891
77.42072539,861
77.47324652,888
77.52576765,881
77.57828878,908
77.63080991,961
77.68333104,906
77.73585217,908
77.7883733,888
77.84089443,896
77.89341556,964
77.94593669,939
77.99845782,917
78.05097895,968
78.10350008,919
78.15602121,951
78.20854234,938
78.26106347,945
78.3135846,873
78.36610573,908
78.41862686,941
78.47114799,914
78.52366912,923
78.57619025,961
78.62871138,942
78.68123251,887
78.73375364,880
78.78627477,933
78.8387959,927
78.89131703,895
78.94383816,902
78.99635929,975
79.04888042,869
79.10140155,934
79.15392268,946
79.20644381,924
79.25896494,930
79.31148607,891
79.3640072,948
79.41652833,938
79.46904946,936
79.52157059,872
79.57409172,971
79.62661285,985
79.67913398,889
79.73165511,959
79.78417624,947
79.83669737,947
79.8892185,1010
79.94173963,844
79.99426076,894
80.04678189,927
80.09930302,971
80.15182415,977
80.20434528,1030
80.25686641,993
80.30938754,986
80.36190867,994
80.4144298,969
80.46695093,969
80.51947206,987
80.57199319,935
80.62451432,899
80.67703545,974
80.72955658,894
80.78207771,905
80.83459884,932
80.88711997,941
80.9396411,890
80.99216223,952
81.04468336,923
81.09720449,1000
81.14972562,921
81.20224675,959
81.25476788,920
81.30728901,901
81.35981014,959
81.41233127,950
81.4648524,943
81.51737353,960
81.56989466,969
81.62241579,949
81.67493692,969
81.72745805,918
81.77997918,913
81.83250031,971
81.88502144,980
81.93754257,1001
81.9900637,974
82.04258483,997
82.09510596,1032
82.14762709,1033
82.20014822,972
82.25266935,1012
82.30519048,1001
82.35771161,1022
82.41023274,1014
82.46275387,1035
82.515275,991
82.56779613,1060
82.62031726,1059
82.67283839,1030
82.72535952,990
82.77788065,1018
82.83040178,1023
82.88292291,1075
82.93544404,1066
82.98796517,1051
83.0404863,1075
83.09300743,1053
83.14552856,1029
83.19804969,1002
83.25057082,1101
83.30309195,1007
83.35561308,1039
83.40813421,1060
83.46065534,985
83.51317647,1055
83.5656976,1023
83.61821873,964
83.67073986,1027
83.72326099,1025
83.77578212,1020
83.82830325,1044
83.88082438,977
83.93334551,1068
83.98586664,1017
84.03838777,935
84.0909089,952
84.14343003,996
84.19595116,1012
84.24847229,946
84.30099342,984
84.35351455,1012
84.40603568,955
84.45855681,956
84.51107794,950
84.56359907,1020
84.6161202,1001
84.66864133,927
84.72116246,947
84.77368359,962
84.82620472,925
84.87872585,923
84.93124698,988
84.98376811,901
85.03628924,979
85.08881037,923
85.1413315,953
85.19385263,916
85.24637376,952
85.29889489,899
85.35141602,929
85.40393715,933
85.45645828,975
85.50897941,906
85.56150054,981
85.61402167,966
85.6665428,937
85.71906393,920
85.77158506,895
85.82410619,992
85.87662732,926
85.92914845,895
85.98166958,908
86.03419071,927
86.08671184,898
86.13923297,929
86.1917541,1005
86.24427523,1002
86.29679636,958
86.34931749,968
86.40183862,968
86.45435975,951
86.50688088,950
86.55940201,939
86.61192314,945
86.66444427,948
86.7169654,970
86.76948653,944
86.82200766,955
86.87452879,957
86.92704992,977
86.97957105,943
87.03209218,987
87.08461331,923
87.13713444,925
87.18965557,889
87.2421767,958
87.29469783,902
87.34721896,956
87.39974009,912
87.45226122,954
87.50478235,1003
87.55730348,981
87.60982461,939
87.66234574,995
87.71486687,920
87.767388,899
87.81990913,970
87.87243026,946
87.92495139,963
87.97747252,920
88.02999365,954
88.08251478,975
88.13503591,948
88.18755704,974
88.24007817,925
88.2925993,912
88.34512043,912
88.39764156,926
88.45016269,954
88.50268382,915
88.55520495,911
88.60772609,917
88.66024722,988
88.71276835,940
88.76528948,967
88.81781061,925
88.87033174,851
88.92285287,962
88.975374,1008
89.02789513,932
89.08041626,957
89.13293739,976
89.18545852,936
89.23797965,990
89.29050078,984
89.34302191,927
89.39554304,1021
89.44806417,933
89.5005853,981
89.55310643,1006
89.60562756,1013
89.65814869,978
89.71066982,992
89.76319095,967
89.81571208,981
89.86823321,967
89.92075434,968
89.97327547,987
89.99953603,1010